[2020-Jun-28 12:03:28] 127.0.0.1 GET http /favicon.ico? 5xx INTERNAL SERVER ERROR
Traceback (most recent call last):
  File "C:\Users\Zviad\Anaconda3\lib\site-packages\flask\app.py", line 1950, in full_dispatch_request
    rv = self.dispatch_request()
  File "C:\Users\Zviad\Anaconda3\lib\site-packages\flask\app.py", line 1926, in dispatch_request
    self.raise_routing_exception(req)
  File "C:\Users\Zviad\Anaconda3\lib\site-packages\flask\app.py", line 1908, in raise_routing_exception
    raise request.routing_exception
  File "C:\Users\Zviad\Anaconda3\lib\site-packages\flask\ctx.py", line 350, in match_request
    result = self.url_adapter.match(return_rule=True)
  File "C:\Users\Zviad\Anaconda3\lib\site-packages\werkzeug\routing.py", line 1799, in match
    raise NotFound()
werkzeug.exceptions.NotFound: 404 Not Found: The requested URL was not found on the server. If you entered the URL manually please check your spelling and try again.

[2020-Jun-29 21:12:44] 127.0.0.1 GET http /favicon.ico? 5xx INTERNAL SERVER ERROR
Traceback (most recent call last):
  File "C:\Users\Zviad\Anaconda3\lib\site-packages\flask\app.py", line 1950, in full_dispatch_request
    rv = self.dispatch_request()
  File "C:\Users\Zviad\Anaconda3\lib\site-packages\flask\app.py", line 1926, in dispatch_request
    self.raise_routing_exception(req)
  File "C:\Users\Zviad\Anaconda3\lib\site-packages\flask\app.py", line 1908, in raise_routing_exception
    raise request.routing_exception
  File "C:\Users\Zviad\Anaconda3\lib\site-packages\flask\ctx.py", line 350, in match_request
    result = self.url_adapter.match(return_rule=True)
  File "C:\Users\Zviad\Anaconda3\lib\site-packages\werkzeug\routing.py", line 1799, in match
    raise NotFound()
werkzeug.exceptions.NotFound: 404 Not Found: The requested URL was not found on the server. If you entered the URL manually please check your spelling and try again.

[2020-Jun-29 21:13:52] 127.0.0.1 POST http /?%7B%22ID%22=%20115,&%22Exposure%22=0.416,&%22LicAge%22=145,&%22Gender%22=%22Female%22,&%22MariStat%22=%22Other%22,&%22DrivAge%22=30,&%22HasKmLimit%22=0,&%22BonusMalus%22=54,&%22OutUseNb%22=1.0,&%22RiskArea%22=10.0,&%22VehUsage%22=%22Private%22,&%22SocioCateg%22=%20%22CSP50%22%7D 5xx INTERNAL SERVER ERROR
Traceback (most recent call last):
  File "C:\Users\Zviad\Anaconda3\lib\site-packages\flask\app.py", line 1950, in full_dispatch_request
    rv = self.dispatch_request()
  File "C:\Users\Zviad\Anaconda3\lib\site-packages\flask\app.py", line 1926, in dispatch_request
    self.raise_routing_exception(req)
  File "C:\Users\Zviad\Anaconda3\lib\site-packages\flask\app.py", line 1908, in raise_routing_exception
    raise request.routing_exception
  File "C:\Users\Zviad\Anaconda3\lib\site-packages\flask\ctx.py", line 350, in match_request
    result = self.url_adapter.match(return_rule=True)
  File "C:\Users\Zviad\Anaconda3\lib\site-packages\werkzeug\routing.py", line 1798, in match
    raise MethodNotAllowed(valid_methods=list(have_match_for))
werkzeug.exceptions.MethodNotAllowed: 405 Method Not Allowed: The method is not allowed for the requested URL.

[2020-Jun-29 21:17:55] 127.0.0.1 GET http /predict? 5xx INTERNAL SERVER ERROR
Traceback (most recent call last):
  File "C:\Users\Zviad\Anaconda3\lib\site-packages\flask\app.py", line 1950, in full_dispatch_request
    rv = self.dispatch_request()
  File "C:\Users\Zviad\Anaconda3\lib\site-packages\flask\app.py", line 1926, in dispatch_request
    self.raise_routing_exception(req)
  File "C:\Users\Zviad\Anaconda3\lib\site-packages\flask\app.py", line 1908, in raise_routing_exception
    raise request.routing_exception
  File "C:\Users\Zviad\Anaconda3\lib\site-packages\flask\ctx.py", line 350, in match_request
    result = self.url_adapter.match(return_rule=True)
  File "C:\Users\Zviad\Anaconda3\lib\site-packages\werkzeug\routing.py", line 1798, in match
    raise MethodNotAllowed(valid_methods=list(have_match_for))
werkzeug.exceptions.MethodNotAllowed: 405 Method Not Allowed: The method is not allowed for the requested URL.

[2020-Jun-29 21:20:33] request from 127.0.0.1: None
[2020-Jun-29 21:20:33] 127.0.0.1 POST http /predict?%7B%22ID%22=%20115,&%22Exposure%22=0.416,&%22LicAge%22=145,&%22Gender%22=%22Female%22,&%22MariStat%22=%22Other%22,&%22DrivAge%22=30,&%22HasKmLimit%22=0,&%22BonusMalus%22=54,&%22OutUseNb%22=1.0,&%22RiskArea%22=10.0,&%22VehUsage%22=%22Private%22,&%22SocioCateg%22=%20%22CSP50%22%7D 5xx INTERNAL SERVER ERROR
Traceback (most recent call last):
  File "C:\Users\Zviad\Anaconda3\lib\site-packages\flask\app.py", line 1950, in full_dispatch_request
    rv = self.dispatch_request()
  File "C:\Users\Zviad\Anaconda3\lib\site-packages\flask\app.py", line 1936, in dispatch_request
    return self.view_functions[rule.endpoint](**req.view_args)
  File "D:/Projects/portfolio_project.git/app.py", line 34, in predict
    id = json_input['ID']
TypeError: 'NoneType' object is not subscriptable

[2020-Jun-29 21:25:50] request from 127.0.0.1: {'ID': 115, 'Exposure': 0.416, 'LicAge': 145, 'Gender': 'Female', 'MariStat': 'Other', 'DrivAge': 30, 'HasKmLimit': 0, 'BonusMalus': 54, 'OutUseNb': 1.0, 'RiskArea': 10.0, 'VehUsage': 'Private', 'SocioCateg': 'CSP50'}
[2020-Jun-29 21:25:50] 127.0.0.1 POST http /predict? 5xx INTERNAL SERVER ERROR
Traceback (most recent call last):
  File "C:\Users\Zviad\Anaconda3\lib\site-packages\flask\app.py", line 1950, in full_dispatch_request
    rv = self.dispatch_request()
  File "C:\Users\Zviad\Anaconda3\lib\site-packages\flask\app.py", line 1936, in dispatch_request
    return self.view_functions[rule.endpoint](**req.view_args)
  File "D:/Projects/portfolio_project.git/app.py", line 35, in predict
    df_get = process_input(json_input)
NameError: name 'process_input' is not defined

[2020-Jun-29 21:31:28] request from 127.0.0.1: {'ID': 115, 'Exposure': 0.416, 'LicAge': 145, 'Gender': 'Female', 'MariStat': 'Other', 'DrivAge': 30, 'HasKmLimit': 0, 'BonusMalus': 54, 'OutUseNb': 1.0, 'RiskArea': 10.0, 'VehUsage': 'Private', 'SocioCateg': 'CSP50'}
[2020-Jun-29 21:31:28] 127.0.0.1 POST http /predict? 5xx INTERNAL SERVER ERROR
Traceback (most recent call last):
  File "C:\Users\Zviad\Anaconda3\lib\site-packages\flask\app.py", line 1950, in full_dispatch_request
    rv = self.dispatch_request()
  File "C:\Users\Zviad\Anaconda3\lib\site-packages\flask\app.py", line 1936, in dispatch_request
    return self.view_functions[rule.endpoint](**req.view_args)
  File "D:/Projects/portfolio_project.git/app.py", line 36, in predict
    df_get = process_input(json_input)
  File "D:\Projects\portfolio_project.git\proces_data.py", line 96, in process_input
    df2=return_pd_Frame()
  File "D:\Projects\portfolio_project.git\proces_data.py", line 74, in return_pd_Frame
    df1=pd.DaTaFrame([0,0,0,0,0,0,0,0,0,0,0,0,0,0,0,0,0,0,0,0],index=columns)
  File "C:\Users\Zviad\AppData\Roaming\Python\Python37\site-packages\pandas\__init__.py", line 214, in __getattr__
    raise AttributeError("module 'pandas' has no attribute '{}'".format(name))
AttributeError: module 'pandas' has no attribute 'DaTaFrame'

[2020-Jun-29 21:32:18] request from 127.0.0.1: {'ID': 115, 'Exposure': 0.416, 'LicAge': 145, 'Gender': 'Female', 'MariStat': 'Other', 'DrivAge': 30, 'HasKmLimit': 0, 'BonusMalus': 54, 'OutUseNb': 1.0, 'RiskArea': 10.0, 'VehUsage': 'Private', 'SocioCateg': 'CSP50'}
[2020-Jun-29 21:32:18] 127.0.0.1 POST http /predict? 5xx INTERNAL SERVER ERROR
Traceback (most recent call last):
  File "C:\Users\Zviad\Anaconda3\lib\site-packages\flask\app.py", line 1950, in full_dispatch_request
    rv = self.dispatch_request()
  File "C:\Users\Zviad\Anaconda3\lib\site-packages\flask\app.py", line 1936, in dispatch_request
    return self.view_functions[rule.endpoint](**req.view_args)
  File "D:/Projects/portfolio_project.git/app.py", line 39, in predict
    prediction_gb['predict']=model.predict(df_get)
  File "C:\Users\Zviad\Anaconda3\lib\site-packages\xgboost\core.py", line 1568, in predict
    type(data))
TypeError: ('Expecting data to be a DMatrix object, got: ', <class 'pandas.core.frame.DataFrame'>)

[2020-Jun-29 21:36:14] request from 127.0.0.1: {'ID': 115, 'Exposure': 0.416, 'LicAge': 145, 'Gender': 'Female', 'MariStat': 'Other', 'DrivAge': 30, 'HasKmLimit': 0, 'BonusMalus': 54, 'OutUseNb': 1.0, 'RiskArea': 10.0, 'VehUsage': 'Private', 'SocioCateg': 'CSP50'}
[2020-Jun-29 21:36:14] 127.0.0.1 POST http /predict? 5xx INTERNAL SERVER ERROR
Traceback (most recent call last):
  File "C:\Users\Zviad\Anaconda3\lib\site-packages\flask\app.py", line 1950, in full_dispatch_request
    rv = self.dispatch_request()
  File "C:\Users\Zviad\Anaconda3\lib\site-packages\flask\app.py", line 1936, in dispatch_request
    return self.view_functions[rule.endpoint](**req.view_args)
  File "D:/Projects/portfolio_project.git/app.py", line 39, in predict
    prediction_gb['predict']=model.predict(df_get)
  File "C:\Users\Zviad\Anaconda3\lib\site-packages\xgboost\core.py", line 1580, in predict
    ctypes.byref(preds)))
  File "C:\Users\Zviad\Anaconda3\lib\site-packages\xgboost\core.py", line 190, in _check_call
    raise XGBoostError(py_str(_LIB.XGBGetLastError()))
xgboost.core.XGBoostError: [21:36:14] C:\Users\Administrator\workspace\xgboost-win64_release_1.1.0\src\learner.cc:1070: Check failed: learner_model_param_.num_feature == p_fmat->Info().num_col_ (20 vs. 22) : Number of columns does not match number of features in booster.

[2020-Jun-29 21:39:16] request from 127.0.0.1: {'ID': 115, 'Exposure': 0.416, 'LicAge': 145, 'Gender': 'Female', 'MariStat': 'Other', 'DrivAge': 30, 'HasKmLimit': 0, 'BonusMalus': 54, 'OutUseNb': 1.0, 'RiskArea': 10.0, 'VehUsage': 'Private', 'SocioCateg': 'CSP50'}
[2020-Jun-29 21:39:16] 127.0.0.1 POST http /predict? 5xx INTERNAL SERVER ERROR
Traceback (most recent call last):
  File "C:\Users\Zviad\Anaconda3\lib\site-packages\flask\app.py", line 1950, in full_dispatch_request
    rv = self.dispatch_request()
  File "C:\Users\Zviad\Anaconda3\lib\site-packages\flask\app.py", line 1936, in dispatch_request
    return self.view_functions[rule.endpoint](**req.view_args)
  File "D:/Projects/portfolio_project.git/app.py", line 39, in predict
    prediction_gb['predict']=model.predict(df_get)
  File "C:\Users\Zviad\Anaconda3\lib\site-packages\xgboost\core.py", line 1580, in predict
    ctypes.byref(preds)))
  File "C:\Users\Zviad\Anaconda3\lib\site-packages\xgboost\core.py", line 190, in _check_call
    raise XGBoostError(py_str(_LIB.XGBGetLastError()))
xgboost.core.XGBoostError: [21:39:16] C:\Users\Administrator\workspace\xgboost-win64_release_1.1.0\src\learner.cc:1070: Check failed: learner_model_param_.num_feature == p_fmat->Info().num_col_ (20 vs. 23) : Number of columns does not match number of features in booster.

[2020-Jun-29 21:46:53] request from 127.0.0.1: {'ID': 115, 'Exposure': 0.416, 'LicAge': 145, 'Gender': 'Female', 'MariStat': 'Other', 'DrivAge': 30, 'HasKmLimit': 0, 'BonusMalus': 54, 'OutUseNb': 1.0, 'RiskArea': 10.0, 'VehUsage': 'Private', 'SocioCateg': 'CSP50'}
[2020-Jun-29 21:46:53] 127.0.0.1 POST http /predict? 5xx INTERNAL SERVER ERROR
Traceback (most recent call last):
  File "C:\Users\Zviad\Anaconda3\lib\site-packages\flask\app.py", line 1950, in full_dispatch_request
    rv = self.dispatch_request()
  File "C:\Users\Zviad\Anaconda3\lib\site-packages\flask\app.py", line 1936, in dispatch_request
    return self.view_functions[rule.endpoint](**req.view_args)
  File "D:/Projects/portfolio_project.git/app.py", line 39, in predict
    prediction_gb['predict']=model.predict(df_get)
  File "C:\Users\Zviad\Anaconda3\lib\site-packages\xgboost\core.py", line 1580, in predict
    ctypes.byref(preds)))
  File "C:\Users\Zviad\Anaconda3\lib\site-packages\xgboost\core.py", line 190, in _check_call
    raise XGBoostError(py_str(_LIB.XGBGetLastError()))
xgboost.core.XGBoostError: [21:46:53] C:\Users\Administrator\workspace\xgboost-win64_release_1.1.0\src\learner.cc:1070: Check failed: learner_model_param_.num_feature == p_fmat->Info().num_col_ (20 vs. 22) : Number of columns does not match number of features in booster.

[2020-Jun-29 21:48:51] request from 127.0.0.1: {'ID': 115, 'Exposure': 0.416, 'LicAge': 145, 'Gender': 'Female', 'MariStat': 'Other', 'DrivAge': 30, 'HasKmLimit': 0, 'BonusMalus': 54, 'OutUseNb': 1.0, 'RiskArea': 10.0, 'VehUsage': 'Private', 'SocioCateg': 'CSP50'}
[2020-Jun-29 21:48:51] 127.0.0.1 POST http /predict? 5xx INTERNAL SERVER ERROR
Traceback (most recent call last):
  File "C:\Users\Zviad\Anaconda3\lib\site-packages\flask\app.py", line 1950, in full_dispatch_request
    rv = self.dispatch_request()
  File "C:\Users\Zviad\Anaconda3\lib\site-packages\flask\app.py", line 1936, in dispatch_request
    return self.view_functions[rule.endpoint](**req.view_args)
  File "D:/Projects/portfolio_project.git/app.py", line 39, in predict
    prediction_gb['predict']=model.predict(df_get)
  File "C:\Users\Zviad\Anaconda3\lib\site-packages\xgboost\core.py", line 1580, in predict
    ctypes.byref(preds)))
  File "C:\Users\Zviad\Anaconda3\lib\site-packages\xgboost\core.py", line 190, in _check_call
    raise XGBoostError(py_str(_LIB.XGBGetLastError()))
xgboost.core.XGBoostError: [21:48:51] C:\Users\Administrator\workspace\xgboost-win64_release_1.1.0\src\learner.cc:1070: Check failed: learner_model_param_.num_feature == p_fmat->Info().num_col_ (20 vs. 22) : Number of columns does not match number of features in booster.

[2020-Jun-29 21:50:35] request from 127.0.0.1: {'ID': 115, 'Exposure': 0.416, 'LicAge': 145, 'Gender': 'Female', 'MariStat': 'Other', 'DrivAge': 30, 'HasKmLimit': 0, 'BonusMalus': 54, 'OutUseNb': 1.0, 'RiskArea': 10.0, 'VehUsage': 'Private', 'SocioCateg': 'CSP50'}
[2020-Jun-29 21:50:35] 127.0.0.1 POST http /predict? 5xx INTERNAL SERVER ERROR
Traceback (most recent call last):
  File "C:\Users\Zviad\Anaconda3\lib\site-packages\flask\app.py", line 1950, in full_dispatch_request
    rv = self.dispatch_request()
  File "C:\Users\Zviad\Anaconda3\lib\site-packages\flask\app.py", line 1936, in dispatch_request
    return self.view_functions[rule.endpoint](**req.view_args)
  File "D:/Projects/portfolio_project.git/app.py", line 39, in predict
    prediction_gb['predict']=model.predict(df_get)
  File "C:\Users\Zviad\Anaconda3\lib\site-packages\xgboost\core.py", line 1580, in predict
    ctypes.byref(preds)))
  File "C:\Users\Zviad\Anaconda3\lib\site-packages\xgboost\core.py", line 190, in _check_call
    raise XGBoostError(py_str(_LIB.XGBGetLastError()))
xgboost.core.XGBoostError: [21:50:35] C:\Users\Administrator\workspace\xgboost-win64_release_1.1.0\src\learner.cc:1070: Check failed: learner_model_param_.num_feature == p_fmat->Info().num_col_ (20 vs. 21) : Number of columns does not match number of features in booster.

[2020-Jun-29 21:51:40] request from 127.0.0.1: {'ID': 115, 'Exposure': 0.416, 'LicAge': 145, 'Gender': 'Female', 'MariStat': 'Other', 'DrivAge': 30, 'HasKmLimit': 0, 'BonusMalus': 54, 'OutUseNb': 1.0, 'RiskArea': 10.0, 'VehUsage': 'Private', 'SocioCateg': 'CSP50'}
[2020-Jun-29 21:51:40] 127.0.0.1 POST http /predict? 5xx INTERNAL SERVER ERROR
Traceback (most recent call last):
  File "C:\Users\Zviad\Anaconda3\lib\site-packages\flask\app.py", line 1950, in full_dispatch_request
    rv = self.dispatch_request()
  File "C:\Users\Zviad\Anaconda3\lib\site-packages\flask\app.py", line 1936, in dispatch_request
    return self.view_functions[rule.endpoint](**req.view_args)
  File "D:/Projects/portfolio_project.git/app.py", line 39, in predict
    prediction_gb['predict']=model.predict(df_get)
  File "C:\Users\Zviad\Anaconda3\lib\site-packages\xgboost\core.py", line 1580, in predict
    ctypes.byref(preds)))
  File "C:\Users\Zviad\Anaconda3\lib\site-packages\xgboost\core.py", line 190, in _check_call
    raise XGBoostError(py_str(_LIB.XGBGetLastError()))
xgboost.core.XGBoostError: [21:51:40] C:\Users\Administrator\workspace\xgboost-win64_release_1.1.0\src\learner.cc:1070: Check failed: learner_model_param_.num_feature == p_fmat->Info().num_col_ (20 vs. 21) : Number of columns does not match number of features in booster.

[2020-Jun-29 21:52:57] request from 127.0.0.1: {'ID': 115, 'Exposure': 0.416, 'LicAge': 145, 'Gender': 'Female', 'MariStat': 'Other', 'DrivAge': 30, 'HasKmLimit': 0, 'BonusMalus': 54, 'OutUseNb': 1.0, 'RiskArea': 10.0, 'VehUsage': 'Private', 'SocioCateg': 'CSP50'}
[2020-Jun-29 21:52:57] 127.0.0.1 POST http /predict? 5xx INTERNAL SERVER ERROR
Traceback (most recent call last):
  File "C:\Users\Zviad\Anaconda3\lib\site-packages\flask\app.py", line 1950, in full_dispatch_request
    rv = self.dispatch_request()
  File "C:\Users\Zviad\Anaconda3\lib\site-packages\flask\app.py", line 1936, in dispatch_request
    return self.view_functions[rule.endpoint](**req.view_args)
  File "D:/Projects/portfolio_project.git/app.py", line 39, in predict
    prediction_gb['predict']=model.predict(df_get)
NameError: name 'prediction_gb' is not defined

[2020-Jun-29 21:54:25] request from 127.0.0.1: {'ID': 115, 'Exposure': 0.416, 'LicAge': 145, 'Gender': 'Female', 'MariStat': 'Other', 'DrivAge': 30, 'HasKmLimit': 0, 'BonusMalus': 54, 'OutUseNb': 1.0, 'RiskArea': 10.0, 'VehUsage': 'Private', 'SocioCateg': 'CSP50'}
[2020-Jun-29 21:54:25] predicted for 0.068017 msec: {'ID': 115, 'value_ClaimsCount': 1410.7043}

[2020-Jun-29 21:54:25] 127.0.0.1 POST http /predict? 5xx INTERNAL SERVER ERROR
Traceback (most recent call last):
  File "C:\Users\Zviad\Anaconda3\lib\site-packages\flask\app.py", line 1950, in full_dispatch_request
    rv = self.dispatch_request()
  File "C:\Users\Zviad\Anaconda3\lib\site-packages\flask\app.py", line 1936, in dispatch_request
    return self.view_functions[rule.endpoint](**req.view_args)
  File "D:/Projects/portfolio_project.git/app.py", line 52, in predict
    return jsonify(result)
  File "C:\Users\Zviad\Anaconda3\lib\site-packages\flask\json\__init__.py", line 370, in jsonify
    dumps(data, indent=indent, separators=separators) + "\n",
  File "C:\Users\Zviad\Anaconda3\lib\site-packages\flask\json\__init__.py", line 211, in dumps
    rv = _json.dumps(obj, **kwargs)
  File "C:\Users\Zviad\Anaconda3\lib\json\__init__.py", line 238, in dumps
    **kw).encode(obj)
  File "C:\Users\Zviad\Anaconda3\lib\json\encoder.py", line 199, in encode
    chunks = self.iterencode(o, _one_shot=True)
  File "C:\Users\Zviad\Anaconda3\lib\json\encoder.py", line 257, in iterencode
    return _iterencode(o, 0)
  File "C:\Users\Zviad\Anaconda3\lib\site-packages\flask\json\__init__.py", line 100, in default
    return _json.JSONEncoder.default(self, o)
  File "C:\Users\Zviad\Anaconda3\lib\json\encoder.py", line 179, in default
    raise TypeError(f'Object of type {o.__class__.__name__} '
TypeError: Object of type float32 is not JSON serializable

[2020-Jun-29 21:59:03] request from 127.0.0.1: {'ID': 115, 'Exposure': 0.416, 'LicAge': 145, 'Gender': 'Female', 'MariStat': 'Other', 'DrivAge': 30, 'HasKmLimit': 0, 'BonusMalus': 54, 'OutUseNb': 1.0, 'RiskArea': 10.0, 'VehUsage': 'Private', 'SocioCateg': 'CSP50'}
[2020-Jun-29 21:59:03] predicted for 0.051012 msec: {'ID': 115, 'value_ClaimsCount': 1410.7043}

[2020-Jun-29 21:59:03] 127.0.0.1 POST http /predict? 5xx INTERNAL SERVER ERROR
Traceback (most recent call last):
  File "C:\Users\Zviad\Anaconda3\lib\site-packages\flask\app.py", line 2447, in wsgi_app
    response = self.full_dispatch_request()
  File "C:\Users\Zviad\Anaconda3\lib\site-packages\flask\app.py", line 1953, in full_dispatch_request
    return self.finalize_request(rv)
  File "C:\Users\Zviad\Anaconda3\lib\site-packages\flask\app.py", line 1968, in finalize_request
    response = self.make_response(rv)
  File "C:\Users\Zviad\Anaconda3\lib\site-packages\flask\app.py", line 2112, in make_response
    rv = jsonify(rv)
  File "C:\Users\Zviad\Anaconda3\lib\site-packages\flask\json\__init__.py", line 370, in jsonify
    dumps(data, indent=indent, separators=separators) + "\n",
  File "C:\Users\Zviad\Anaconda3\lib\site-packages\flask\json\__init__.py", line 211, in dumps
    rv = _json.dumps(obj, **kwargs)
  File "C:\Users\Zviad\Anaconda3\lib\json\__init__.py", line 238, in dumps
    **kw).encode(obj)
  File "C:\Users\Zviad\Anaconda3\lib\json\encoder.py", line 199, in encode
    chunks = self.iterencode(o, _one_shot=True)
  File "C:\Users\Zviad\Anaconda3\lib\json\encoder.py", line 257, in iterencode
    return _iterencode(o, 0)
  File "C:\Users\Zviad\Anaconda3\lib\site-packages\flask\json\__init__.py", line 100, in default
    return _json.JSONEncoder.default(self, o)
  File "C:\Users\Zviad\Anaconda3\lib\json\encoder.py", line 179, in default
    raise TypeError(f'Object of type {o.__class__.__name__} '
TypeError: Object of type float32 is not JSON serializable

[2020-Jun-29 22:05:28] request from 127.0.0.1: {'ID': 115, 'Exposure': 0.416, 'LicAge': 145, 'Gender': 'Female', 'MariStat': 'Other', 'DrivAge': 30, 'HasKmLimit': 0, 'BonusMalus': 54, 'OutUseNb': 1.0, 'RiskArea': 10.0, 'VehUsage': 'Private', 'SocioCateg': 'CSP50'}
[2020-Jun-29 22:05:28] predicted for 0.052011 msec: {'ID': 115, 'value_ClaimsCount': 1410}

[2020-Jun-29 22:21:54] request from 127.0.0.1: {'ID': 115, 'LicAge': 145, 'Gender': 'Female', 'MariStat': 'Other', 'DrivAge': 30, 'HasKmLimit': 0, 'BonusMalus': 54, 'OutUseNb': 1.0, 'RiskArea': 10.0, 'VehUsage': 'Private', 'SocioCateg': 'CSP50'}
[2020-Jun-29 22:21:54] predicted for 0.067021 msec: {'ID': 115, 'value_ClaimsCount': 1410}

[2020-Jun-29 22:22:23] request from 127.0.0.1: {'ID': 125, 'LicAge': 145, 'Gender': 'Male', 'MariStat': 'Other', 'DrivAge': 20, 'HasKmLimit': 0, 'BonusMalus': 34, 'OutUseNb': 1.0, 'RiskArea': 10.0, 'VehUsage': 'Private', 'SocioCateg': 'CSP20'}
[2020-Jun-29 22:22:23] predicted for 0.031004 msec: {'ID': 125, 'value_ClaimsCount': 750}

[2020-Jun-29 22:24:03] 127.0.0.1 GET http /predict? 5xx INTERNAL SERVER ERROR
Traceback (most recent call last):
  File "C:\Users\Zviad\Anaconda3\lib\site-packages\flask\app.py", line 1950, in full_dispatch_request
    rv = self.dispatch_request()
  File "C:\Users\Zviad\Anaconda3\lib\site-packages\flask\app.py", line 1926, in dispatch_request
    self.raise_routing_exception(req)
  File "C:\Users\Zviad\Anaconda3\lib\site-packages\flask\app.py", line 1908, in raise_routing_exception
    raise request.routing_exception
  File "C:\Users\Zviad\Anaconda3\lib\site-packages\flask\ctx.py", line 350, in match_request
    result = self.url_adapter.match(return_rule=True)
  File "C:\Users\Zviad\Anaconda3\lib\site-packages\werkzeug\routing.py", line 1798, in match
    raise MethodNotAllowed(valid_methods=list(have_match_for))
werkzeug.exceptions.MethodNotAllowed: 405 Method Not Allowed: The method is not allowed for the requested URL.

[2020-Jun-29 22:24:12] 127.0.0.1 GET http /predict? 5xx INTERNAL SERVER ERROR
Traceback (most recent call last):
  File "C:\Users\Zviad\Anaconda3\lib\site-packages\flask\app.py", line 1950, in full_dispatch_request
    rv = self.dispatch_request()
  File "C:\Users\Zviad\Anaconda3\lib\site-packages\flask\app.py", line 1926, in dispatch_request
    self.raise_routing_exception(req)
  File "C:\Users\Zviad\Anaconda3\lib\site-packages\flask\app.py", line 1908, in raise_routing_exception
    raise request.routing_exception
  File "C:\Users\Zviad\Anaconda3\lib\site-packages\flask\ctx.py", line 350, in match_request
    result = self.url_adapter.match(return_rule=True)
  File "C:\Users\Zviad\Anaconda3\lib\site-packages\werkzeug\routing.py", line 1798, in match
    raise MethodNotAllowed(valid_methods=list(have_match_for))
werkzeug.exceptions.MethodNotAllowed: 405 Method Not Allowed: The method is not allowed for the requested URL.

